2025-07-29 18:25:27,706 - httpx - INFO - HTTP Request: POST https://api.telegram.org/botYOUR_TELEGRAM_BOT_TOKEN/getMe "HTTP/1.1 404 Not Found"
2025-07-29 18:25:27,707 - telegram.ext - ERROR - Network Retry Loop (Bootstrap Initialize Application): Invalid token. Aborting retry loop.
Traceback (most recent call last):
  File "/home/jules/.pyenv/versions/3.12.11/lib/python3.12/site-packages/telegram/_bot.py", line 845, in initialize
    await self.get_me()
  File "/home/jules/.pyenv/versions/3.12.11/lib/python3.12/site-packages/telegram/ext/_extbot.py", line 1981, in get_me
    return await super().get_me(
           ^^^^^^^^^^^^^^^^^^^^^
  File "/home/jules/.pyenv/versions/3.12.11/lib/python3.12/site-packages/telegram/_bot.py", line 976, in get_me
    result = await self._post(
             ^^^^^^^^^^^^^^^^^
  File "/home/jules/.pyenv/versions/3.12.11/lib/python3.12/site-packages/telegram/_bot.py", line 698, in _post
    return await self._do_post(
           ^^^^^^^^^^^^^^^^^^^^
  File "/home/jules/.pyenv/versions/3.12.11/lib/python3.12/site-packages/telegram/ext/_extbot.py", line 370, in _do_post
    return await super()._do_post(
           ^^^^^^^^^^^^^^^^^^^^^^^
  File "/home/jules/.pyenv/versions/3.12.11/lib/python3.12/site-packages/telegram/_bot.py", line 727, in _do_post
    result = await request.post(
             ^^^^^^^^^^^^^^^^^^^
  File "/home/jules/.pyenv/versions/3.12.11/lib/python3.12/site-packages/telegram/request/_baserequest.py", line 197, in post
    result = await self._request_wrapper(
             ^^^^^^^^^^^^^^^^^^^^^^^^^^^^
  File "/home/jules/.pyenv/versions/3.12.11/lib/python3.12/site-packages/telegram/request/_baserequest.py", line 374, in _request_wrapper
    raise exception
telegram.error.InvalidToken: Not Found

The above exception was the direct cause of the following exception:

Traceback (most recent call last):
  File "/home/jules/.pyenv/versions/3.12.11/lib/python3.12/site-packages/telegram/ext/_utils/networkloop.py", line 115, in network_retry_loop
    if not await do_action():
           ^^^^^^^^^^^^^^^^^
  File "/home/jules/.pyenv/versions/3.12.11/lib/python3.12/site-packages/telegram/ext/_utils/networkloop.py", line 93, in do_action
    return await action_cb()
           ^^^^^^^^^^^^^^^^^
  File "/home/jules/.pyenv/versions/3.12.11/lib/python3.12/site-packages/telegram/ext/_application.py", line 489, in initialize
    await self.bot.initialize()
  File "/home/jules/.pyenv/versions/3.12.11/lib/python3.12/site-packages/telegram/ext/_extbot.py", line 316, in initialize
    await super().initialize()
  File "/home/jules/.pyenv/versions/3.12.11/lib/python3.12/site-packages/telegram/_bot.py", line 847, in initialize
    raise InvalidToken(f"The token `{self._token}` was rejected by the server.") from exc
telegram.error.InvalidToken: The token `YOUR_TELEGRAM_BOT_TOKEN` was rejected by the server.
